Workbook
Name DBアクセスツール保管場所: [2]アクセス情報!$B$2
Name EAI_DB開発機ＩＰアドレス: [2]アクセス情報!$B$13
Name EAI開発機IPアドレス: [2]アクセス情報!$B$3
Name EAI管理テーブル・インスタンス: [2]アクセス情報!$B$5
Name EAI管理テーブル・スキーマ: [2]アクセス情報!$B$9
Name EAI管理テーブル・接続パスワード: [2]アクセス情報!$B$7
Name EAI管理テーブル・接続ユーザ: [2]アクセス情報!$B$6
Name FTPアクセスツール保管場所: [2]アクセス情報!$B$4
Name Java配置場所: [2]アクセス情報!$B$1
Name インタフェーステーブルIPアドレス: [2]アクセス情報!$B$14
Name 取得EAIデータ: [2]EAIデータ!$A:$BS
Name 取得EAIデータ2: [2]EAIデータ!$B:$BS
Name 連係元No: [2]制御!$G$6

Sheet 表紙
H13: BC80-EAIシステム
H18: b.アプリケーション開発
H20: 07.プログラム仕様
H22: 02.プログラム機能仕様
H24: EAIテストデータ作成ツール
AL36: ドキュメントID | AR36: =変更履歴!A2 -> BC80b07_02
AL38: バージョン | AR38: =変更履歴!BB2 -> 3.0
AL40: 作成日 | AR40: =変更履歴!AP2 -> 46568
AL42: 更新日 | AR42: =変更履歴!AT2 -> 46568

Sheet 変更履歴
A1: ドキュメントID | G1: ドキュメント名称 | AP1: 作成日 | AT1: 更新日 | AX1: 更新者 | BB1: バージョン
A2: BC80b07_02 | G2: =表紙!H20&" - "&RIGHT(CELL("filename",A1),LEN(CELL("filename",A1))-FIND("]",CELL("filename",A1))) -> 07.プログラム仕様 - 変更履歴 | AP2: =MIN(F6:I35) -> 46568 | AT2: =MAX(F6:I35) -> 46568 | AX2: =INDIRECT(ADDRESS(COUNTA(J6:P35)+5,10)) -> STNet 板東 | BB2: =INDIRECT(ADDRESS(COUNTA(B6:E35)+5,2)) -> 3.0
A4: 変 更 履 歴
A5: No | B5: バージョン | F5: 更新日 | J5: 更新者 | Q5: 内容
A6: =ROW()-5 -> 1 | B6: 3.0 | F6: 46568 | J6: STNet 板東 | Q6: 新規作成
A7: =ROW()-5 -> 2
A8: =ROW()-5 -> 3
A9: =ROW()-5 -> 4
A10: =ROW()-5 -> 5
A11: =ROW()-5 -> 6
A12: =ROW()-5 -> 7
A13: =ROW()-5 -> 8
A14: =ROW()-5 -> 9
A15: =ROW()-5 -> 10
A16: =ROW()-5 -> 11
A17: =ROW()-5 -> 12
A18: =ROW()-5 -> 13
... A35: =ROW()-5 -> 30

Sheet 1. 概要
A1: ドキュメントID | G1: ドキュメント名称 | AP1: 作成日 | AT1: 更新日 | AX1: 更新者 | BB1: バージョン
A2: BC80b02_03 | G2: =表紙!H20&" - "&RIGHT(CELL("filename",A1),LEN(CELL("filename",A1))-FIND("]",CELL("filename",A1))) -> 07.プログラム仕様 - 1. 概要 | AP2: =変更履歴!AP2 -> 46568 | AT2: =変更履歴!AT2 -> 46568 | AX2: =変更履歴!AX2 -> STNet 板東 | BB2: =変更履歴!BB2 -> 3.0
B4: 1. 概要
C5: 連係元IF外部設計書と連係先IF外部設計書の情報をもとに、単体テストで使用する入力テストデータと単体テスト仕様書を出力する。
C6: 現行でテストデータ作成ツール（EAIテストデータ作成ツール）と単体テスト仕様書作成ツール（単体テスト仕様書作成.xlsm）は別のツールであるが、どちらもIF外部設計書を
C7: インプットとしているため、
C8: 「単体テスト仕様書作成.xlsm」の機能を「EAIテストデータ作成ツール（Java）」に統合し、1つのJavaアプリケーションにする。
C10: 1.1 概要図
D11: [現行]
D21: [改修後]
C31: 1.2. 各ツール概要
D32: 1.2.1 EAIテストデータ作成用Excel作成マクロ.xlsm
E33: 連係元外部設計書と連係先外部設計書から、EAIテストデータ作成ツールの入力となるEAIテストデータ作成用Excelを出力する。
E34: [EAIテストデータ作成用Excelの出力仕様]
F35: 連係元外部設計書をベースにし、シート構成や内容は変更せず、同列に連係先外部設計書の対応する情報を追記する。
F36: また、「データ構造」シートに各レコード単位の出力データ件数指定欄、「項目定義(№xx)」シートに各項目単位での固定値指定欄を追加する。
E37: ※詳細は 「補足. 現行マクロの説明」 参照
D40: 1.2.2 EAIテストデータ作成ツール
E41: EAIテストデータ作成用Excelと単体テスト仕様書を読み込み、
E42: テストケースを自動決定し、単体テスト用入力データおよび単体テスト仕様書を作成する。
E43: 入力用テストデータの各レコードは、EAIテストデータ作成用Excelの出力データ数指定の件数分出力する。
E45: コンポーネント | K45: 内容 | T45: 備考
E46: 実行環境 | K46: Java25 / SpringBoot | T46: ユーザにJarを配布
E47: UI | K47: HTML | T47: setting.ymlに画面から設定するためのフォーム、生成ボタン、エラー有無表示
E48: 設定管理 | K48: setting.yml | T48: 画面から設定された外部設定値の保管
E50: [変更点（テストデータ / 仕様書）]
F51: [UT]
G52: ・DB連係機能は廃止済であるため、考慮しないよう変更
G53: ・以下のテストケースについては、「BC80e01_04_インタフェース基本テストケース.xlsx」の仕様通りに出力できるよう修正する。
H54: ① 001-103 可変長桁数オーバー
I55: 連係元バイト数よりも連係先バイト数のほうが多い場合：連係先桁数+5桁のデータを出力
I56: 上記以外：連係元桁数+5桁のデータを出力
H58: ② 001-215 可変長桁数オーバー(スペース)
I59: 連係元が可変長かつTrimをしない項目がある場合に本テストデータを出力
J60: [Trimをしない項目の条件]
K61: ・Trim欄、固定値欄、Date欄がすべて指定されていない
H63: ③ 002-102xxxx 日付(YYYYYMMDD)
I64: 連係元が可変長かつ連係先項目のDATE欄に"/追加"が指定されている場合に本テストデータを出力
F66: [ITa]
G67: ・送信元の連係後処理の"送信時アクション"が「削除」または「処理なし」の場合に、
...

Sheet 2.1. 基本動作
A1: ドキュメントID | G1: ドキュメント名称 | AP1: 作成日 | AT1: 更新日 | AX1: 更新者 | BB1: バージョン
A2: BC80b02_03 | G2: =表紙!H20&" - "&RIGHT(CELL("filename",A1),LEN(CELL("filename",A1))-FIND("]",CELL("filename",A1))) -> 07.プログラム仕様 - 2.1. 基本動作 | AP2: =変更履歴!AP2 -> 46568 | AT2: =変更履歴!AT2 -> 46568 | AX2: =変更履歴!AX2 -> STNet 板東 | BB2: =変更履歴!BB2 -> 3.0
B4: 2. 機能仕様
C6: 2.1 基本動作
D7: 本ツールの処理の流れは、以下のとおり。
D8: 途中で処理に失敗した場合はエラーとし、以降の処理を行わない。
E10: (1) EAIテストデータ作成用Excelの各シート取込
F11: ・概要・環境
G12: 連係方式（マッピング/パススルー）、文字コード、データ形式（可変長・固定長)、改行コード等を取得する。
F13: ・データ構造
G14: レコード種別を判別する。
F15: ・項目定義
G16: 連係元および連係先の各項目の項目定義を取得する。
E18: (2) 出力テストケース決定
F19: (1)で取得した情報をもとに作成が必要なテストケースを決定する。
F20: テストケースの決定条件は、「BC80e01_04_インタフェース基本テストケース.xlsx」参照。
E22: (3) テストデータ出力
F23: 出力対象のテストケースについて、(1)で取得した項目定義仕様に基づいたデータを出力する。
E25: (4) 単体テスト仕様書作成
F26: 仕様書の雛形Excelをベースに、(2)で決定したテストケースと、(1)で取り込んだEAIテストデータ作成用Excelに対応したテスト仕様書を出力する。

Sheet 2.2. ツール構成
A1: ドキュメントID | G1: ドキュメント名称 | AP1: 作成日 | AT1: 更新日 | AX1: 更新者 | BB1: バージョン
A2: BC80b02_03 | G2: =表紙!H20&" - "&RIGHT(CELL("filename",A1),LEN(CELL("filename",A1))-FIND("]",CELL("filename",A1))) -> 07.プログラム仕様 - 2.2. ツール構成 | AP2: =変更履歴!AP2 -> 46568 | AT2: =変更履歴!AT2 -> 46568 | AX2: =変更履歴!AX2 -> STNet 板東 | BB2: =変更履歴!BB2 -> 3.0
C4: 2.2 ツール構成
D6: yonden-eai-create-testdata
E7: └ | F7: create-testdata.jar | T7: テストデータ作成ツールの実行Jarファイル
E8: └ | F8: create-testdata-run.bat | T8: Jarファイル実行用のバッチファイル
E9: └ | F9: config
F10: └ | G10: setting.yml | T10: 画面から設定された項目値を設定するymlファイル
E11: └ | F11: template
F12: └ | G12: 単体テスト仕様書作成_雛形_単体テスト仕様書兼結果確認書.xlsx
E13: └ | F13: logs
F14: └ | G14: [連係元IFID]To[連係先IFID]-testdata.log | T14: 実行結果ログ（ツール内の各処理実行結果を出力）

Sheet 2.3. 機能仕様
A1: ドキュメントID | G1: ドキュメント名称 | AP1: 作成日 | AT1: 更新日 | AX1: 更新者 | BB1: バージョン
A2: BC80b02_03 | G2: =表紙!H20&" - "&RIGHT(CELL("filename",A1),LEN(CELL("filename",A1))-FIND("]",CELL("filename",A1))) -> 07.プログラム仕様 - 2.3. 機能仕様 | AP2: =変更履歴!AP2 -> 46568 | AT2: =変更履歴!AT2 -> 46568 | AX2: =変更履歴!AX2 -> STNet 板東 | BB2: =変更履歴!BB2 -> 3.0
C4: 2.3 機能仕様
D5: 2.3.1 入力仕様
E6: (1) 入力項目
F7: No | G7: 画面項目名 | P7: 種別 | V7: 備考
F8: 1 | G8: 単体テストデータ出力先 | P8: フォルダ
F9: 2 | G9: 単体テスト仕様書出力先 | P9: フォルダ
F10: 3 | G10: EAIテストデータ作成用Excel | P10: Excel
F11: 4 | G11: 単体テスト仕様書雛形 | P11: Excel
F12: 5 | G12: 案件名 | P12: テキストボックス | V12: 単体テスト仕様書の機能名に記載
F13: 6 | G13: 単体テスト担当者 | P13: テキストボックス | V13: 単体テスト仕様書の担当者欄に記載
E15: (2) 実行画面イメージ
E32: (3) 入力チェック
F33: 生成ボタン押下時、以下の入力チェックを実施する。
F34: 入力チェックまたはファイル生成時にエラーとなった場合は処理を中断し、該当するエラーメッセージを画面および実行結果ログファイルに表示する。
F36: ・画面入力項目チェック
G37: ケース | U37: メッセージ
G38: 出力先に設定したフォルダが存在しない場合 | U38: [出力先]のフォルダが存在しません。
G39: 出力先に設定したフォルダが権限不足の場合 | U39: [出力先]のフォルダの権限がないため、出力できません。
G40: 連係元,先ファイルファイルを開いている場合 | U40: [ファイル名]が他のプログラム（Excel等）で開かれているためアクセスできません。
G41: 連係元,先ファイルが存在しない場合 | U41: [ファイル名]が存在しません。
G42: 入力ファイルが選択されていない場合 | U42: [ファイル名]を選択してください。
G43: ファイル拡張子が異なっている場合 | U43: ファイルの形式が正しくありません。（.xlsmを指定してください）
G44: ファイルサイズが0Byteの場合 | U44: 指定されたファイルの内容が空（0Byte）です。
G45: ファイルサイズが1MBより大きい場合 | U45: ファイルサイズが上限（1MB）を超えているため、処理できません。
F48: ・ファイル取込チェック
G49: ケース | U49: メッセージ
G50: 入力ファイルの読み取りに失敗した場合 | U50: [ファイル]の読み込みに失敗しました。
G51: EAIテストデータ作成用Excelの各シートの読み込みに失敗した場合 | U51: [シート名]の読み込み中にエラーが発生しました。
G52: テストデータの出力ディレクトリが存在する場合 ※確認ダイアログを出力 | U52: 出力ディレクトリが存在します。上書きしますか？
G53: テストデータのファイル出力に失敗した場合 | U53: テストデータのファイル出力に失敗しました。
G54: 単体テスト仕様書の出力に失敗した場合 | U54: 単体テスト仕様書の出力に失敗しました。
D57: 2.3.2 出力仕様
E59: (1) 出力ファイル仕様
F61: (1)-1 単体テストデータ
G62: [連係元IFID]to[連係先IFID]フォルダを作成し、その配下にテストデータ一式を出力する。
G63: 出力ファイル名等の仕様は「BC80e01_04_インタフェース基本テストケース.xlsx」参照
H65: [テストデータ出力先ディレクトリ」
H66: └ | I66: [連係元IFID]To[連係先IFID]
...

Sheet 2.3 別紙_仕様書出力仕様
A1: ドキュメントID | G1: ドキュメント名称 | AP1: 作成日 | AT1: 更新日 | AX1: 更新者 | BB1: バージョン
A2: BC80b02_03 | G2: =表紙!H20&" - "&RIGHT(CELL("filename",A1),LEN(CELL("filename",A1))-FIND("]",CELL("filename",A1))) -> 07.プログラム仕様 - 2.3 別紙_仕様書出力仕様 | AP2: =変更履歴!AP2 -> 46568 | AT2: =変更履歴!AT2 -> 46568 | AX2: =変更履歴!AX2 -> STNet 板東 | BB2: =変更履歴!BB2 -> 3.0
B4: 別紙. 単体テスト仕様書兼結果確認書
C6: [仕様書構成]
D7: No | E7: シート名 | P7: 備考
D8: 1 | E8: 表紙
D9: 2 | E9: 改訂履歴
D10: 3 | E10: 単体テスト仕様書（マッピング） | P10: 単体テスト（UT）用のテスト仕様書
D11: 3 | E11: 結合テスト仕様書（連係処理） | P11: 内部結合テスト（Ita）用のテスト仕様書
C14: 各シートは、以下の仕様で作成する。
D15: ① 表紙
E16: 列 | K16: 記載内容
E17: H11 | K17: [5.案件名]
E20: AP42（機能ID） | K20: [連係元IFID]To[連係先IFID]
E23: AP44（機能名） | K23: [連係元インタフェース名]
D28: ② 改定履歴
E29: 列 | K29: 記載内容
E30: B6（バージョン） | K30: 1.0
E33: F6（改定日） | K33: [現在日付]
E36: J6（改定者） | K36: [6.単体テスト担当者]
E39: Q6（改定内容） | K39: 新規作成
D45: ③ 単体テスト仕様書（マッピング）
E47: ・取り込んだテストデータのテストケース毎に、単体テスト仕様書雛形の中から対応するテスト仕様を決定し、テスト項目のxxx-xxxの部分を該当するテストケースに置き換えて仕様書に追加する。
F49: [ケースの選択仕様（単体テスト仕様書雛形の「単体テスト仕様書（マッピング）」から抜粋）]
G50: No | I50: テスト項目 | S50: 確認内容 | AI50: 選択条件
G51: =1 -> 1 | I51: ケースID： xxx-xxxテストデータの確認 | S51: 変換後データが出力され、連係ログにエラーが発生しないことを確認 | AI51: ・正常系ケース
G55: 2 | I55: ケースID： xxx-xxxテストデータの確認 (データ比較) | S55: 想定する出力データと比較を行い、変換後データが外部設計書の仕様と一致することを確認 | AI55: ・正常系ケース
G59: 3 | I59: ケースID：101-001 ０件レコードファイルの確認 | S59: ０件レコードファイルが正常に連係されることを確認 | AI59: ・テストケース101-001
G63: 4 | I63: ケースID： xxx-xxxテストデータの確認 | S63: 変換後データが出力され、連係ログにエラーが発生することを確認 （変換処理継続） | AI63: 変換後データが出力され、連係ログにエラーが発生しないことを確認
G67: 5 | I67: ケースID： xxx-xxxテストデータの確認 (データ比較) | S67: 想定する出力データと比較を行い、変換後データが外部設計書の仕様と一致することを確認 | AI67: 変換後データが出力され、連係ログにエラーが発生しないことを確認
G71: 6 | I71: ケースID： xxx-xxxテストデータの確認 | S71: 連係ログにエラーが発生し、処理が途中終了することを確認 | AI71: 変換後データが出力され、連係ログにエラーが発生しないことを確認
F77: [単体テスト仕様書（マッピング）] 出力イメージ
H84: すべてのテスト項目に対する連番 | AD84: 6. 単体テスト担当者 | AR84: インタフェース基本テストケース(UT)の該当ケースの「ケース名」
E87: ・テストケースに項目Noが付与されている異常系データについては、対応する連係元項目No.と項目名称（日本語）を吹き出し等で出力する。
F88: [出力イメージ]
D94: ④ 結合テスト仕様書（連係処理）
E96: ・EAIテストデータ作成用Excelの「概要・環境」シートの内容を基に、単体テスト仕様書雛形の中から対象のケースを選択し、単体テスト仕様書に追加する。
F98: [ケースの選択仕様（単体テスト仕様書雛形の「単体テスト仕様書（マッピング）」から抜粋）]
G99: No | I99: テスト項目 | S99: 確認内容 | AI99: 列 | AL99: 選択条件
G100: 1 | I100: 送信元の連係処理 （FTP取り込み） | S100: トリガファイルを設置し、連係元ディレクトリに設置した連係元ファイルが正常に取り込まれることを確認 | AI100: - | AL100: -
...

Sheet 補足. 現行マクロの説明
A1: ドキュメントID | G1: ドキュメント名称 | AP1: 作成日 | AT1: 更新日 | AX1: 更新者 | BB1: バージョン
A2: BC80b02_03 | G2: =表紙!H20&" - "&RIGHT(CELL("filename",A1),LEN(CELL("filename",A1))-FIND("]",CELL("filename",A1))) -> 07.プログラム仕様 - 補足. 現行マクロの説明 | AP2: =変更履歴!AP2 -> 46568 | AT2: =変更履歴!AT2 -> 46568 | AX2: =変更履歴!AX2 -> STNet 板東 | BB2: =変更履歴!BB2 -> 3.0
B4: 補足. 現行マクロの説明
C6: (1) EAIテストデータ作成用Excel作成マクロ
D8: EAIテストデータ作成ツールの入力となるEAIテストデータ作成用Excelを出力する。
E9: ・連係元外部設計書と連係先外部設計書をもとに作成する。
E10: ・連係元外部設計書をベースにし、シート構成や内容は変更せず、連係先外部設計書の情報を追加する。
E11: ・追加項目として、以下の入力欄を追加する。
F12: -「データ構造」シート→各レコード単位での出力データ件数指定欄
F13: -「項目定義(№xx)」シート→各連係元項目単位での固定値指定欄
E16: [各シート内容]
K17: 内容 | AB17: 追加項目
F18: 変更履歴 | AB18: なし
F19: 概要・環境 | K19: 連係方式（マッピング/パススルー）、文字コード、データ形式（可変長・固定長)、改行コード等 | AB19: なし
F20: データ構造 | K20: レコードの構造 | AB20: 各レコード単位の出力データ件数を指定する欄をAU列に追加し、デフォルトで4を指定
F21: 項目定義(№xx) | K21: 各レコードの項目定義 xxは通番 | AB21: 連係元項目に対応する連係先の項目情報を取得し、以下の情報をAU列以降に追記する。 （列：項目） AU：固定値 / 属性、AV：ﾚｺｰﾄﾞNo、AW：項目No、AX：属性、AY：ﾊﾞｲﾄ数、AZ：符号、BA：整数桁数、BB：小数桁数、BC：ｴﾗｰ時動作、BD：Trim、BE：項目名（日本語）、BF：項目名（ID）、BG：編集詳細
F24: データ構造シート - 追加項目：各レコード単位での出力データ件数指定欄
F33: 項目定義(№xx)シート - 追加項目：各連係元項目単位での固定値指定欄
